<?xml version="1.0" encoding="utf-8"?>
<!-- This URDF was automatically created by SolidWorks to URDF Exporter with friction parameters for Isaac Sim -->
<robot
  name="ski">
  
  <material name="wheel_material">
    <contact>
      <rolling_friction value="0.1"/>
      <spinning_friction value="0.1"/>
      <static_friction value="1.0"/>
      <dynamic_friction value="1.0"/>
      <restitution value="0.1"/>
    </contact>
  </material>
  
  <material name="base_material">
    <contact>
      <rolling_friction value="0.05"/>
      <spinning_friction value="0.05"/>
      <static_friction value="0.8"/>
      <dynamic_friction value="0.8"/>
      <restitution value="0.2"/>
    </contact>
  </material>
  
  <link
    name="base_link">
    <inertial>
      <origin
        xyz="-2.2998E-07 9.74E-09 0.081029"
        rpy="0 0 0" />
      <mass
        value="3.1846" />
      <inertia
        ixx="0.049043"
        ixy="-1.5821E-08"
        ixz="-4.3995E-09"
        iyy="0.083631"
        iyz="1.8621E-10"
        izz="0.13258" />
    </inertial>
    <visual>
      <origin
        xyz="0 0 0"
        rpy="0 0 0" />
      <geometry>
        <mesh
          filename="package://ski/meshes/base_link.STL" />
      </geometry>
      <material name="base_material"/>
    </visual>
    <collision>
      <origin
        xyz="0 0 0"
        rpy="0 0 0" />
      <geometry>
        <mesh
          filename="package://ski/meshes/base_link.STL" />
      </geometry>
      <contact>
        <static_friction value="0.8"/>
        <dynamic_friction value="0.8"/>
        <restitution value="0.2"/>
      </contact>
      <material name="base_material"/>
    </collision>
  </link>
  
  <link
    name="tr0">
    <inertial>
      <origin
        xyz="-0.0039479 1.3746E-05 0.002543"
        rpy="0 0 0" />
      <mass
        value="0.054711" />
      <inertia
        ixx="7.6178E-05"
        ixy="4.236E-09"
        ixz="-1.6794E-07"
        iyy="6.5079E-06"
        iyz="3.528E-09"
        izz="7.7065E-05" />
    </inertial>
    <visual>
      <origin
        xyz="0 0 0"
        rpy="0 0 0" />
      <geometry>
        <mesh
          filename="package://ski/meshes/tr0.STL" />
      </geometry>
      <material name="base_material"/>
    </visual>
    <collision>
      <origin
        xyz="0 0 0"
        rpy="0 0 0" />
      <geometry>
        <mesh
          filename="package://ski/meshes/tr0.STL" />
      </geometry>
      <contact>
        <static_friction value="0.6"/>
        <dynamic_friction value="0.6"/>
      </contact>
    </collision>
  </link>
  
  <joint
    name="trj0"
    type="revolute">
    <origin
      xyz="0.24845 0 0.025"
      rpy="0 0.38044 0" />
    <parent
      link="base_link" />
    <child
      link="tr0" />
    <axis
      xyz="0 0 -1" />
    <limit
      lower="0"
      upper="0"
      effort="0"
      velocity="0" />
  </joint>
  
  <link
    name="wh0">
    <inertial>
      <origin
        xyz="0 0 0"
        rpy="0 0 0" />
      <mass
        value="0.049078" />
      <inertia
        ixx="1.141E-05"
        ixy="2.8791E-23"
        ixz="-5.7056E-24"
        iyy="1.6312E-05"
        iyz="5.0372E-22"
        izz="1.141E-05" />
    </inertial>
    <visual>
      <origin
        xyz="0 0 0"
        rpy="0 0 0" />
      <geometry>
        <mesh
          filename="package://ski/meshes/wh0.STL" />
      </geometry>
      <material name="wheel_material"/>
    </visual>
    <collision>
      <origin
        xyz="0 0 0"
        rpy="0 0 0" />
      <geometry>
        <mesh
          filename="package://ski/meshes/wh0.STL" />
      </geometry>
      <contact>
        <static_friction value="1.0"/>
        <dynamic_friction value="1.0"/>
        <rolling_friction value="0.1"/>
        <spinning_friction value="0.1"/>
        <restitution value="0.1"/>
      </contact>
      <material name="wheel_material"/>
    </collision>
  </link>
  
  <joint
    name="whj0"
    type="continuous">
    <origin
      xyz="0 -0.079 0"
      rpy="0 -0.38044 0" />
    <parent
      link="tr0" />
    <child
      link="wh0" />
    <axis
      xyz="0 1 0" />
    <dynamics damping="0.01" friction="0.01"/>
  </joint>
  
  <link
    name="wh1">
    <inertial>
      <origin
        xyz="2.7756E-17 0 0"
        rpy="0 0 0" />
      <mass
        value="0.049078" />
      <inertia
        ixx="1.141E-05"
        ixy="2.8791E-23"
        ixz="-5.6925E-24"
        iyy="1.6312E-05"
        iyz="5.0392E-22"
        izz="1.141E-05" />
    </inertial>
    <visual>
      <origin
        xyz="0 0 0"
        rpy="0 0 0" />
      <geometry>
        <mesh
          filename="package://ski/meshes/wh1.STL" />
      </geometry>
      <material name="wheel_material"/>
    </visual>
    <collision>
      <origin
        xyz="0 0 0"
        rpy="0 0 0" />
      <geometry>
        <mesh
          filename="package://ski/meshes/wh1.STL" />
      </geometry>
      <contact>
        <static_friction value="1.0"/>
        <dynamic_friction value="1.0"/>
        <rolling_friction value="0.1"/>
        <spinning_friction value="0.1"/>
        <restitution value="0.1"/>
      </contact>
      <material name="wheel_material"/>
    </collision>
  </link>
  
  <joint
    name="whj1"
    type="continuous">
    <origin
      xyz="0 0.079 0"
      rpy="0 -0.38044 0" />
    <parent
      link="tr0" />
    <child
      link="wh1" />
    <axis
      xyz="0 1 0" />
    <dynamics damping="0.01" friction="0.01"/>
  </joint>
  
  <link
    name="tr1">
    <inertial>
      <origin
        xyz="0 0 0"
        rpy="0 0 0" />
      <mass
        value="0" />
      <inertia
        ixx="0"
        ixy="0"
        ixz="0"
        iyy="0"
        iyz="0"
        izz="0" />
    </inertial>
    <visual>
      <origin
        xyz="0 0 0"
        rpy="0 0 0" />
      <geometry>
        <mesh
          filename="package://ski/meshes/tr1.STL" />
      </geometry>
      <material name="base_material"/>
    </visual>
    <collision>
      <origin
        xyz="0 0 0"
        rpy="0 0 0" />
      <geometry>
        <mesh
          filename="package://ski/meshes/tr1.STL" />
      </geometry>
      <contact>
        <static_friction value="0.6"/>
        <dynamic_friction value="0.6"/>
      </contact>
    </collision>
  </link>
  
  <joint
    name="trj1"
    type="revolute">
    <origin
      xyz="-0.24845 0 0.025"
      rpy="0 0.38044 3.1416" />
    <parent
      link="base_link" />
    <child
      link="tr1" />
    <axis
      xyz="0 0 -1" />
    <limit
      lower="0"
      upper="0"
      effort="0"
      velocity="0" />
  </joint>
  
  <link
    name="wh2">
    <inertial>
      <origin
        xyz="-2.7756E-17 0 3.4694E-18"
        rpy="0 0 0" />
      <mass
        value="0.049078" />
      <inertia
        ixx="1.141E-05"
        ixy="8.5336E-23"
        ixz="8.0295E-23"
        iyy="1.6312E-05"
        iyz="3.9668E-22"
        izz="1.141E-05" />
    </inertial>
    <visual>
      <origin
        xyz="0 0 0"
        rpy="0 0 0" />
      <geometry>
        <mesh
          filename="package://ski/meshes/wh2.STL" />
      </geometry>
      <material name="wheel_material"/>
    </visual>
    <collision>
      <origin
        xyz="0 0 0"
        rpy="0 0 0" />
      <geometry>
        <mesh
          filename="package://ski/meshes/wh2.STL" />
      </geometry>
      <contact>
        <static_friction value="1.0"/>
        <dynamic_friction value="1.0"/>
        <rolling_friction value="0.1"/>
        <spinning_friction value="0.1"/>
        <restitution value="0.1"/>
      </contact>
      <material name="wheel_material"/>
    </collision>
  </link>
  
  <joint
    name="whj2"
    type="continuous">
    <origin
      xyz="0 0.079 0"
      rpy="0 0.38044 3.1416" />
    <parent
      link="tr1" />
    <child
      link="wh2" />
    <axis
      xyz="0 1 0" />
    <dynamics damping="0.01" friction="0.01"/>
  </joint>
  
  <link
    name="wh3">
    <inertial>
      <origin
        xyz="-2.7756E-17 1.3878E-17 0"
        rpy="0 0 0" />
      <mass
        value="0.049078" />
      <inertia
        ixx="1.141E-05"
        ixy="2.9498E-23"
        ixz="7.6507E-23"
        iyy="1.6312E-05"
        iyz="3.9541E-22"
        izz="1.141E-05" />
    </inertial>
    <visual>
      <origin
        xyz="0 0 0"
        rpy="0 0 0" />
      <geometry>
        <mesh
          filename="package://ski/meshes/wh3.STL" />
      </geometry>
      <material name="wheel_material"/>
    </visual>
    <collision>
      <origin
        xyz="0 0 0"
        rpy="0 0 0" />
      <geometry>
        <mesh
          filename="package://ski/meshes/wh3.STL" />
      </geometry>
      <contact>
        <static_friction value="1.0"/>
        <dynamic_friction value="1.0"/>
        <rolling_friction value="0.1"/>
        <spinning_friction value="0.1"/>
        <restitution value="0.1"/>
      </contact>
      <material name="wheel_material"/>
    </collision>
  </link>
  
  <joint
    name="whj3"
    type="continuous">
    <origin
      xyz="0 -0.079 0"
      rpy="0 0.38044 3.1416" />
    <parent
      link="tr1" />
    <child
      link="wh3" />
    <axis
      xyz="0 1 0" />
    <dynamics damping="0.01" friction="0.01"/>
  </joint>
</robot>